[32m2023-08-22 23:58:25 +0545[0m - dagster - [34mDEBUG[0m - __ASSET_JOB - 72e240e7-fc40-4252-9d6a-35959baee790 - 8360 - LOGS_CAPTURED - Started capturing logs in process (pid: 8360).
[32m2023-08-22 23:58:25 +0545[0m - dagster - [34mDEBUG[0m - __ASSET_JOB - 72e240e7-fc40-4252-9d6a-35959baee790 - 8360 - api__github_commits - STEP_START - Started execution of step "api__github_commits".
unxz: commits.tsv: File exists
[32m2023-08-22 23:58:27 +0545[0m - dagster - [34mERROR[0m - [31m__ASSET_JOB - 72e240e7-fc40-4252-9d6a-35959baee790 - 8360 - api__github_commits - STEP_FAILURE - Execution of step "api__github_commits" failed.

dagster._core.errors.DagsterExecutionStepExecutionError: Error occurred while executing op "api__github_commits"::

TypeError: object of type 'int' has no len()

Stack Trace:
  File "/home/kushal/PROJECTS/dagster_github_metrics/dagster-dbt-test-env/lib/python3.10/site-packages/dagster/_core/execution/plan/utils.py", line 54, in op_execution_error_boundary
    yield
  File "/home/kushal/PROJECTS/dagster_github_metrics/dagster-dbt-test-env/lib/python3.10/site-packages/dagster/_utils/__init__.py", line 445, in iterate_with_context
    next_output = next(iterator)
  File "/home/kushal/PROJECTS/dagster_github_metrics/dagster-dbt-test-env/lib/python3.10/site-packages/dagster/_core/execution/plan/compute.py", line 125, in gen_from_async_gen
    yield loop.run_until_complete(async_gen.__anext__())
  File "/usr/lib/python3.10/asyncio/base_events.py", line 646, in run_until_complete
    return future.result()
  File "/home/kushal/PROJECTS/dagster_github_metrics/dagster-dbt-test-env/lib/python3.10/site-packages/dagster/_core/execution/plan/compute_generator.py", line 92, in _coerce_async_op_to_async_gen
    result = await awaitable
  File "/home/kushal/PROJECTS/dagster_github_metrics/dagster_github_metrics/assets/api/api_github_commits.py", line 16, in github_commits
    "Non-empty items": len(10),
[0m
