[32m2023-08-23 00:08:43 +0545[0m - dagster - [34mDEBUG[0m - __ASSET_JOB - ad1ea33e-87c9-412d-94ce-b9c13652f288 - 27688 - LOGS_CAPTURED - Started capturing logs in process (pid: 27688).
[32m2023-08-23 00:08:43 +0545[0m - dagster - [34mDEBUG[0m - __ASSET_JOB - ad1ea33e-87c9-412d-94ce-b9c13652f288 - 27688 - api__github_commits - STEP_START - Started execution of step "api__github_commits".
unxz: commits.tsv: File exists
[32m2023-08-23 00:08:45 +0545[0m - dagster - [34mERROR[0m - [31m__ASSET_JOB - ad1ea33e-87c9-412d-94ce-b9c13652f288 - 27688 - api__github_commits - STEP_FAILURE - Execution of step "api__github_commits" failed.

dagster._core.errors.DagsterInvariantViolationError: Error with output for op "api__github_commits": received Output object for output 'result' which does not have an Output annotation. Annotation has type <class 'NoneType'>.

Stack Trace:
  File "/home/kushal/PROJECTS/dagster_github_metrics/dagster-dbt-test-env/lib/python3.10/site-packages/dagster/_core/execution/plan/execute_plan.py", line 273, in dagster_event_sequence_for_step
    for step_event in check.generator(step_events):
  File "/home/kushal/PROJECTS/dagster_github_metrics/dagster-dbt-test-env/lib/python3.10/site-packages/dagster/_core/execution/plan/execute_step.py", line 406, in core_dagster_event_sequence_for_step
    for user_event in check.generator(
  File "/home/kushal/PROJECTS/dagster_github_metrics/dagster-dbt-test-env/lib/python3.10/site-packages/dagster/_core/execution/plan/execute_step.py", line 92, in _step_output_error_checked_user_event_sequence
    for user_event in user_event_sequence:
  File "/home/kushal/PROJECTS/dagster_github_metrics/dagster-dbt-test-env/lib/python3.10/site-packages/dagster/_core/execution/plan/compute.py", line 192, in execute_core_compute
    for step_output in _yield_compute_results(step_context, inputs, compute_fn):
  File "/home/kushal/PROJECTS/dagster_github_metrics/dagster-dbt-test-env/lib/python3.10/site-packages/dagster/_core/execution/plan/compute.py", line 161, in _yield_compute_results
    for event in iterate_with_context(
  File "/home/kushal/PROJECTS/dagster_github_metrics/dagster-dbt-test-env/lib/python3.10/site-packages/dagster/_utils/__init__.py", line 445, in iterate_with_context
    next_output = next(iterator)
  File "/home/kushal/PROJECTS/dagster_github_metrics/dagster-dbt-test-env/lib/python3.10/site-packages/dagster/_core/execution/plan/compute.py", line 125, in gen_from_async_gen
    yield loop.run_until_complete(async_gen.__anext__())
  File "/usr/lib/python3.10/asyncio/base_events.py", line 646, in run_until_complete
    return future.result()
  File "/home/kushal/PROJECTS/dagster_github_metrics/dagster-dbt-test-env/lib/python3.10/site-packages/dagster/_core/execution/plan/compute_generator.py", line 93, in _coerce_async_op_to_async_gen
    for event in validate_and_coerce_op_result_to_iterator(result, context, output_defs):
  File "/home/kushal/PROJECTS/dagster_github_metrics/dagster-dbt-test-env/lib/python3.10/site-packages/dagster/_core/execution/plan/compute_generator.py", line 260, in validate_and_coerce_op_result_to_iterator
    raise DagsterInvariantViolationError(
[0m
