[32m2023-08-23 00:04:22 +0545[0m - dagster - [34mDEBUG[0m - __ASSET_JOB - 6a57cf5a-a5e3-4894-a697-a64a1e88483c - 19382 - LOGS_CAPTURED - Started capturing logs in process (pid: 19382).
[32m2023-08-23 00:04:22 +0545[0m - dagster - [34mDEBUG[0m - __ASSET_JOB - 6a57cf5a-a5e3-4894-a697-a64a1e88483c - 19382 - api__github_commits - STEP_START - Started execution of step "api__github_commits".
[32m2023-08-23 00:05:21 +0545[0m - dagster - [34mERROR[0m - [31m__ASSET_JOB - 6a57cf5a-a5e3-4894-a697-a64a1e88483c - 19382 - api__github_commits - STEP_FAILURE - Execution of step "api__github_commits" failed.

dagster._core.errors.DagsterExecutionInterruptedError

Stack Trace:
  File "/home/kushal/PROJECTS/dagster_github_metrics/dagster-dbt-test-env/lib/python3.10/site-packages/dagster/_core/execution/plan/execute_plan.py", line 273, in dagster_event_sequence_for_step
    for step_event in check.generator(step_events):
  File "/home/kushal/PROJECTS/dagster_github_metrics/dagster-dbt-test-env/lib/python3.10/site-packages/dagster/_core/execution/plan/execute_step.py", line 406, in core_dagster_event_sequence_for_step
    for user_event in check.generator(
  File "/home/kushal/PROJECTS/dagster_github_metrics/dagster-dbt-test-env/lib/python3.10/site-packages/dagster/_core/execution/plan/execute_step.py", line 92, in _step_output_error_checked_user_event_sequence
    for user_event in user_event_sequence:
  File "/home/kushal/PROJECTS/dagster_github_metrics/dagster-dbt-test-env/lib/python3.10/site-packages/dagster/_core/execution/plan/compute.py", line 192, in execute_core_compute
    for step_output in _yield_compute_results(step_context, inputs, compute_fn):
  File "/home/kushal/PROJECTS/dagster_github_metrics/dagster-dbt-test-env/lib/python3.10/site-packages/dagster/_core/execution/plan/compute.py", line 161, in _yield_compute_results
    for event in iterate_with_context(
  File "/home/kushal/PROJECTS/dagster_github_metrics/dagster-dbt-test-env/lib/python3.10/site-packages/dagster/_utils/__init__.py", line 445, in iterate_with_context
    next_output = next(iterator)
  File "/home/kushal/PROJECTS/dagster_github_metrics/dagster-dbt-test-env/lib/python3.10/site-packages/dagster/_core/execution/plan/compute.py", line 125, in gen_from_async_gen
    yield loop.run_until_complete(async_gen.__anext__())
  File "/usr/lib/python3.10/asyncio/base_events.py", line 646, in run_until_complete
    return future.result()
  File "/home/kushal/PROJECTS/dagster_github_metrics/dagster-dbt-test-env/lib/python3.10/site-packages/dagster/_core/execution/plan/compute_generator.py", line 92, in _coerce_async_op_to_async_gen
    result = await awaitable
  File "/home/kushal/PROJECTS/dagster_github_metrics/dagster_github_metrics/assets/api/api_github_commits.py", line 12, in github_commits
    await github_api.fetch_file_data(url=url,dirName=os.getcwd()+'/dagster_github_metrics/data/commits/',fileName='commits.tsv.xz')
  File "/home/kushal/PROJECTS/dagster_github_metrics/dagster_github_metrics/resources/__init__.py", line 26, in fetch_file_data
    urllib.request.urlretrieve(url,fileName)
  File "/usr/lib/python3.10/urllib/request.py", line 270, in urlretrieve
    block = fp.read(bs)
  File "/usr/lib/python3.10/http/client.py", line 465, in read
    s = self.fp.read(amt)
  File "/usr/lib/python3.10/socket.py", line 705, in readinto
    return self._sock.recv_into(b)
  File "/usr/lib/python3.10/ssl.py", line 1274, in recv_into
    return self.read(nbytes, buffer)
  File "/usr/lib/python3.10/ssl.py", line 1130, in read
    return self._sslobj.read(len, buffer)
  File "/home/kushal/PROJECTS/dagster_github_metrics/dagster-dbt-test-env/lib/python3.10/site-packages/dagster/_utils/interrupts.py", line 82, in _new_signal_handler
    raise error_cls()
[0m
